понедельник, 16 июня 2014 г. 20:16:16 (MSK)
Traceback (most recent call last):
  File "/Users/vladsaveliev/vagrant/reporting_suite/targetcov_summary.py", line 81, in <module>
    main(sys.argv)
  File "/Users/vladsaveliev/vagrant/reporting_suite/targetcov_summary.py", line 27, in main
    summarize_cov_gene_report(out_dirpath, samples_fname, report_basedir)
  File "/Users/vladsaveliev/vagrant/reporting_suite/targetcov_summary.py", line 59, in summarize_cov_gene_report
    with open(samples_fname, 'r') as f:
IOError: [Errno 2] No such file or directory: 'sample1,sampl+e2'
понедельник, 16 июня 2014 г. 20:16:16 (MSK)
